# Python 常见标准异常

[toc]

Python为每一种异常定制了一个类型，然后提供了一种特定的语法结构用来进行异常处理.

## 1. 处理 ZeroDivisionError

ZeroDivisionError : 除数为 0 的异常，这是一个数学常识，如果在数学运行中没有考虑这样一个因素就有可能引发这一样一个异常。

```python
try:
    print(5/0)
except ZeroDivisionError:   # 'ZeroDivisionError' 除数等于 0 的报错方式
    print("You can't divide by zero!")
```

- 例子：

```python
print("Enter two numbers.")
print("Enter 'q' to quit.")

while True:

    first_number = input("\nfirst_number: ")
    if first_number == 'q':
        break
    second_number = input("second_number: ")
    if second_number == 'q':
        break
    try:
        result = int(first_number)/int(second_number)
    except ZeroDivisionError:
        print("You can't divide by 0.")
    else:	# 依赖于 try ... 执行成功的放入 e
        print('result = {0}'.format(result))
```

- output

```txt
Enter two numbers.
Enter 'q' to quit.

first_number: 2
second_number: 3
result = 0.6666666666666666

first_number: 4
second_number: 0
You can't divide by 0.

first_number: q

```



## 2. 使用异常避免崩溃

发生错误时，如果程序还有工作没有完成，妥善地处理错误就尤其重要。

这种情况经常会出现在要求用户提供输入的程序中；如果程序能够妥善地处理无效输入，就能再提示用户提供有效输入，而不至于崩溃。

```python
print("Give me two numbers, and I'll divide them.")
print("Enter 'q' to quit.")
while True:
    first_number = input("\nFirst Number: ")
    if first_number == 'q':
        break
    second_number = input("Second Number: ")
    if second_number == 'q':
        break
    answer = int(first_number)/int(second_number)
    print(answer)
```

- Output

```txt
Give me two numbers, and I'll divide them.
Enter 'q' to quit.

First Number: 3
Second Number: 4
0.75

First Number: 2
Second Number: 0
Traceback (most recent call last):
  File "C:/Users/xxnzj/Documents/Files/Code/Python/Quize.py", line 10, in <module>
    answer = int(first_number)/int(second_number)
ZeroDivisionError: division by zero
```



这个程序没有采取任何处理错误的措施，因此让它执行除数为0的除法运算时，它将崩溃.

程序崩溃会给用户带来操作不友好的负面效果。不懂技术的用户会被它们搞糊涂，而且如果用户怀有恶意，他会通过traceback获悉你不希望他知道的信息。

例如，他将知道你的程序文件的名称，还将看到部分不能正确运行的代码。有时候，训练有素的攻击者可根据这些信息判断出可对你的代码发起什么样的攻击。

通过将可能引发错误的代码放在try…except代码块中，可提高这个程序抵御错误的能力。错误是执行除法运算的代码行导致的，因此需要将它放到try…except代码块中。这个实例还包含一个else代码块；依赖于try代码块成功执行的代码都应放到else代码块中。

```python
print("Enter two numbers.")
print("Enter 'q' to quit.")

while True:

    first_number = input("\nfirst_number: ")
    if first_number == 'q':
        break
    second_number = input("second_number: ")
    try:
        answer = int(first_number)/int(second_number)
    except ZeroDivisionError:
        print("You can't divide by 0!")
    else:
        print(answer)
```

- Output

```txt
Enter two numbers.
Enter 'q' to quit.

first_number: 3
second_number: 4
0.75

first_number: 0
second_number: 0
You can't divide by 0!

first_number: q
```

让Python尝试执行try代码块中的除法运算，这个代码块只包含可能导致错误的代码。依赖于try代码块成功执行的代码都放在else代码块中。

在这个实例中，如果除法运算成功，就使用else代码块来打印结果。

**except代码块告诉Python，出现ZeroDivisionError异常时该怎么办**。如果try代码块因除零错误而失败，就打印一条友好的消息，告诉用户如何避免这种错误。程序将继续运行，用户根本看不到traceback。

## 3.处理 FileNotFoundError

文件为空异常，在操作文件中经常遇到。

```python
filename = 'tom.txt'        # tom 这个文件是不存在的
try:
    with open(filename) as file:
        content = file.read()
except FileNotFoundError:   # 文件不能找到的异常处理
    print("Sorry! The file " + filename + " can't find.")
else:   # 依赖于 try ... 执行成功的放入 e
    pass
```

- 例子 （一）：

```python
filename = 'old man and sea.txt'  # 这里的文件是存在
try:
    with open(filename, 'rb') as file:  # 注意: 这里的阅读模式要用 'rb' 以二进制的形式读取
        contents = file.read()
except FileNotFoundError:
    print("Sorry! We don't find " + filename + ".")
else:
    # 计算文件大概有多少单词
    words = contents.split()  # 按空格拆分单词
    num_words = len(words)
    print("The file " + file + " has about " + str(num_words) + " words.")

```

- 读取失败

```txt
Sorry! We don't find old man and sea.txt.
```

- 读取成功

```txt
The file old man and sea.txt has about 8 words.
```

- 例子 （二）：使用函数的方式

  ```python
  def count_words(filename):
      try:
          with open(filename, 'rb') as file:
              contents = file.read()
      except FileNotFoundError:
          print("Sorry! We don't find " + filename + ".")
      else:
          # 计算文件大概有多少单词
          words = contents.split()    # 按空格拆分单词
          num_words = len(words)
          print("The file " + filename + " has about " + str(num_words) + " words.")
  
  count_words("Security Introduce.txt")
  count_words("Old Man and Sea.txt")
  
  ```

  

  

- 输出

  ```python
  Sorry! We don't find Security Introduce.txt.
  The file Old Man and Sea.txt has about 8 words.
  ```

  

### 4. 万能异常 Exception

万能异常 Exception，即**可以捕获任意异常**

```python
s1 = 'hello'
try:
    int(s1)
except Exception as e:
    print(e)
else:   # 依赖于 try 成功执行引入 e
```

- 输出

```txt
invalid literal for int() with base 10: 'hello'
```

#### 万能异常 Exception 的讨论

1. 如果想要的效果是，无论出现什么异常，统一丢弃或者使用同一段代码逻辑去处理，这时只有一个Exception就足够了。

   ```python
   s1 = 'hello'
   try:
       int(s1)
   except Exception as e:
       # 丢弃或者执行其他逻辑
       print(e)
   ```

   

​		如果统一用Exception，没错，是可以捕捉所有异常，但意味着你在处理所有异常时都使用同		

​		一个逻辑去处理（这里说的逻辑即当前expect下面跟的代码块）。

2. 如果想要的效果是，对于不同的异常需要定制不同的处理逻辑，那就需要用到多分支了。

- 多分支处理：

  ```python
  s1 = 'hello'
  try:
      int(s1)
  except IndexError as e:
      print(e)
  except KeyError as e:
      print(e)
  except ValueError as e:
      print(e)
  ```

  

- 多分支 + Exception

  ```python
  s1 = 'hello'
  try:
      int(s1)
  except IndexError as e:
      print(e)
  except KeyError as e:
      print(e)
  except ValueError as e:
      print(e)
  except Exception as e:
      print(e)
  ```

- 其他形式的异常

  ```python
  s1 = 'hello'
  try:
      int(s1)
  except IndexError as e:
      print(e)
  except KeyError as e:
      print(e)
  except ValueError as e:
      print(e)
  # except Exception as e:
  #     print(e)
  else:
      print("try 内代码块没有异常则执行 else 代码")
  finally:
      print("无论异常与否，都会执行该模块，通常是进行清理工作")
  ```

  

### 5. 自定义异常

python 异常分为两种：

- 内建异常，即Python自己定义的异常
- 用户自定义异常，即自定义异常扩展了异常机制

<img src="Resources\04.jpg" style="zoom:80%;" />

可以看到Python的异常有个大基类，然后继承的是Exception。所以自定义类也必须继承Exception。

- 自定义异常类的语法格式

  ```python
  # 最简单的自定义异常
  class FError(Exception):
      pass
  ```

- 抛出异常用 try...except:

  ```python
  try:
      raise FError("自定义异常")
  except FError as e:
      print(e)
  ```

  

- 一个简单的自定义异常类模板

  ```python
  class CustomError(Exception):
      def __init__(self,ErrorInfo):
          super().__init__(self)  # 初始化父类
          self.errorinfo = ErrorInfo
  
      def __str__(self):
          return self.errorinfo
  
  if __name__ == '__main__':
      try:
          raise CustomError("客户异常")
      except CustomError as e:
          print(e)
  ```

  